<?xml version="1.0" ?>
<sdf version="1.6">
  <world name="shapes">
    <plugin
      filename="ignition-gazebo-physics-system"
      name="ignition::gazebo::systems::Physics">
    </plugin>
    <plugin
      filename="ignition-gazebo-user-commands-system"
      name="ignition::gazebo::systems::UserCommands">
    </plugin>
    <plugin
      filename="ignition-gazebo-scene-broadcaster-system"
      name="ignition::gazebo::systems::SceneBroadcaster">
    </plugin>
    <plugin
      filename="ignition-gazebo-sensors-system"
      name="ignition::gazebo::systems::Sensors">
      <render_engine>ogre2</render_engine>
    </plugin>

    <gui fullscreen="1">

      <!-- 3D scene -->
      <plugin filename="MinimalScene" name="3D View">
        <ignition-gui>
          <title>3D View</title>
          <property type="bool" key="showTitleBar">false</property>
          <property type="string" key="state">docked</property>
        </ignition-gui>

        <engine>ogre2</engine>
        <scene>scene</scene>
        <ambient_light>0.4 0.4 0.4</ambient_light>
        <background_color>0.8 0.8 0.8</background_color>
        <camera_pose>-6 0 6 0 0.5 0</camera_pose>
      </plugin>

      <!-- Plugins that add functionality to the scene -->
      <plugin filename="EntityContextMenuPlugin" name="Entity context menu">
        <ignition-gui>
          <property key="state" type="string">floating</property>
          <property key="width" type="double">5</property>
          <property key="height" type="double">5</property>
          <property key="showTitleBar" type="bool">false</property>
        </ignition-gui>
      </plugin>
      <plugin filename="GzSceneManager" name="Scene Manager">
        <ignition-gui>
          <property key="resizable" type="bool">false</property>
          <property key="width" type="double">5</property>
          <property key="height" type="double">5</property>
          <property key="state" type="string">floating</property>
          <property key="showTitleBar" type="bool">false</property>
        </ignition-gui>
      </plugin>
      <plugin filename="InteractiveViewControl" name="Interactive view control">
        <ignition-gui>
          <property key="resizable" type="bool">false</property>
          <property key="width" type="double">5</property>
          <property key="height" type="double">5</property>
          <property key="state" type="string">floating</property>
          <property key="showTitleBar" type="bool">false</property>
        </ignition-gui>
      </plugin>
      <plugin filename="CameraTracking" name="Camera Tracking">
        <ignition-gui>
          <property key="resizable" type="bool">false</property>
          <property key="width" type="double">5</property>
          <property key="height" type="double">5</property>
          <property key="state" type="string">floating</property>
          <property key="showTitleBar" type="bool">false</property>
        </ignition-gui>
      </plugin>
      <!-- World control -->
      <plugin filename="WorldControl" name="World control">
        <ignition-gui>
          <title>World control</title>
          <property type="bool" key="showTitleBar">false</property>
          <property type="bool" key="resizable">false</property>
          <property type="double" key="height">72</property>
          <property type="double" key="width">121</property>
          <property type="double" key="z">1</property>

          <property type="string" key="state">floating</property>
          <anchors target="3D View">
            <line own="left" target="left"/>
            <line own="bottom" target="bottom"/>
          </anchors>
        </ignition-gui>

        <play_pause>true</play_pause>
        <step>true</step>
        <start_paused>true</start_paused>
        <use_event>true</use_event>

      </plugin>

      <!-- World statistics -->
      <plugin filename="WorldStats" name="World stats">
        <ignition-gui>
          <title>World stats</title>
          <property type="bool" key="showTitleBar">false</property>
          <property type="bool" key="resizable">false</property>
          <property type="double" key="height">110</property>
          <property type="double" key="width">290</property>
          <property type="double" key="z">1</property>

          <property type="string" key="state">floating</property>
          <anchors target="3D View">
            <line own="right" target="right"/>
            <line own="bottom" target="bottom"/>
          </anchors>
        </ignition-gui>

        <sim_time>true</sim_time>
        <real_time>true</real_time>
        <real_time_factor>true</real_time_factor>
        <iterations>true</iterations>
      </plugin>

      <!-- Inspector -->
      <plugin filename="ComponentInspector" name="Component inspector">
        <ignition-gui>
          <property type="string" key="state">docked_collapsed</property>
        </ignition-gui>
      </plugin>

      <!-- Entity tree -->
      <plugin filename="EntityTree" name="Entity tree">
        <ignition-gui>
          <property type="string" key="state">docked_collapsed</property>
        </ignition-gui>
      </plugin>

      <!-- Image Display Plugins for visualization -->
      <plugin filename="ImageDisplay" name="Image Display">
        <ignition-gui>
        </ignition-gui>
        <topic>semantic/colored_map</topic>
      </plugin>
      <plugin filename="ImageDisplay" name="Image Display">
        <ignition-gui>
        </ignition-gui>
        <topic>panoptic/colored_map</topic>
      </plugin>
      <plugin filename="ImageDisplay" name="Image Display">
        <ignition-gui>
        </ignition-gui>
        <topic>semantic/labels_map</topic>
      </plugin>
    </gui>

    <light type="directional" name="sun">
      <cast_shadows>true</cast_shadows>
      <pose>0 0 10 0 0 0</pose>
      <diffuse>0.8 0.8 0.8 1</diffuse>
      <specular>0.2 0.2 0.2 1</specular>
      <attenuation>
        <range>1000</range>
        <constant>0.9</constant>
        <linear>0.01</linear>
        <quadratic>0.001</quadratic>
      </attenuation>
      <direction>-0.5 0.1 -0.9</direction>
    </light>

    <model name="ground_plane">
      <static>true</static>
      <link name="link">
        <collision name="collision">
          <geometry>
            <plane>
              <normal>0 0 1</normal>
              <size>100 100</size>
            </plane>
          </geometry>
        </collision>
        <visual name="visual">
          <geometry>
            <plane>
              <normal>0 0 1</normal>
              <size>100 100</size>
            </plane>
          </geometry>
          <material>
            <ambient>0.8 0.8 0.8 1</ambient>
            <diffuse>0.8 0.8 0.8 1</diffuse>
            <specular>0.8 0.8 0.8 1</specular>
          </material>
        </visual>
      </link>
    </model>

    <!-- Cars, all of them have label 40 -->
    <include>
      <name>Car1</name>
      <pose>-2 -2 0 0 0 0</pose>
      <uri>
        https://fuel.ignitionrobotics.org/1.0/OpenRobotics/models/Hatchback blue
      </uri>
      <plugin filename="ignition-gazebo-label-system" name="ignition::gazebo::systems::Label">
        <label>40</label>
      </plugin>
    </include>

    <include>
      <name>Car2</name>
      <pose>-3 -5 0 0 0 0</pose>
      <uri>
        https://fuel.ignitionrobotics.org/1.0/OpenRobotics/models/Pickup
      </uri>
      <plugin filename="ignition-gazebo-label-system" name="ignition::gazebo::systems::Label">
        <label>40</label>
      </plugin>
    </include>

    <include>
      <name>Car3</name>
      <pose>-4 3 0 0 0 -1.57</pose>
      <uri>
        https://fuel.ignitionrobotics.org/1.0/OpenRobotics/models/SUV
      </uri>
      <plugin filename="ignition-gazebo-label-system" name="ignition::gazebo::systems::Label">
        <label>40</label>
      </plugin>
    </include>

    <!-- Tree, all of them have label 30 -->
    <include>
      <name>tree1</name>
      <pose>-2 5 0 0 0 0</pose>
      <uri>
        https://fuel.ignitionrobotics.org/1.0/OpenRobotics/models/Pine Tree
      </uri>
      <plugin filename="ignition-gazebo-label-system" name="ignition::gazebo::systems::Label">
        <label>30</label>
      </plugin>
    </include>

    <include>
      <name>tree2</name>
      <pose>-7 2 0 0 0 0</pose>
      <uri>
        https://fuel.ignitionrobotics.org/1.0/OpenRobotics/models/Pine Tree
      </uri>
      <plugin filename="ignition-gazebo-label-system" name="ignition::gazebo::systems::Label">
        <label>30</label>
      </plugin>
    </include>

    <include>
      <name>tree3</name>
      <pose>-7 -4 0 0 0 0</pose>
      <uri>
        https://fuel.ignitionrobotics.org/1.0/OpenRobotics/models/Pine Tree
      </uri>
      <plugin filename="ignition-gazebo-label-system" name="ignition::gazebo::systems::Label">
        <label>30</label>
      </plugin>
    </include>
    
    <!-- Stairs, all of them have label 5 -->
    <model name="stairs 1" >
      <pose>50 0 0  0 0 0</pose>
      <static>true</static>
      <link name="body" >
        <visual name="visual">
          <plugin filename="ignition-gazebo-label-system" name="ignition::gazebo::systems::Label">
            <label>5</label>
          </plugin>
          <geometry>
            <mesh>
             <scale>.1 .1 .1</scale>
             <uri>meshes/stairs_0020.dae</uri>
            </mesh>
          </geometry>
        </visual>
      </link>
    </model>


    <!-- Cones, all with label 20-->
    <include>
      <name>cone2</name>
      <pose>0 4 0 0 0 1.570796</pose>
      <uri>
        https://fuel.ignitionrobotics.org/1.0/OpenRobotics/models/Construction Cone
      </uri>
      <plugin filename="ignition-gazebo-label-system" name="ignition::gazebo::systems::Label">
        <label>20</label>
      </plugin>
    </include>

    <include>
      <name>cone3</name>
      <pose>2 -2 0 0 0.0 1.57</pose>
      <uri>
        https://fuel.ignitionrobotics.org/1.0/OpenRobotics/models/Construction Cone
      </uri>
      <plugin filename="ignition-gazebo-label-system" name="ignition::gazebo::systems::Label">
        <label>20</label>
      </plugin>
    </include>

    <!-- Semantic Segmentation Camera Sensor -->
    <model name="semantic_camera">
      <pose relative_to="vehicle_blue">0 0 .7 0 0.0 0</pose>
      <link name="link">
        <pose>0 0 0 0 0 0</pose>
        <inertial>
          <mass>0.5</mass>
          <inertia>
            <ixx>0.000166667</ixx>
            <iyy>0.000166667</iyy>
            <izz>0.000166667</izz>
          </inertia>
        </inertial>
        <collision name="collision">
          <geometry>
            <box>
              <size>0.1 0.1 0.1</size>
            </box>
          </geometry>
        </collision>
        <visual name="visual">
          <geometry>
            <box>
              <size>0.1 0.1 0.1</size>
            </box>
          </geometry>
        </visual>
        <sensor name="semantic_segmentation_camera" type="segmentation">
          <topic>semantic</topic>
          <camera>
            <segmentation_type>semantic</segmentation_type>
            <horizontal_fov>1.57</horizontal_fov>
            <image>
              <width>800</width>
              <height>600</height>
            </image>
            <clip>
              <near>0.1</near>
              <far>100</far>
            </clip>
            <!-- uncomment these lines to save segmentation data -->
            <!--
            <save enabled="true">
              <path>segmentation_data/semantic_camera</path>
            </save>
            -->
          </camera>
          <always_on>1</always_on>
          <update_rate>30</update_rate>
          <visualize>true</visualize>
        </sensor>
      </link>
    </model>
    <model name='vehicle_blue' canonical_link='chassis'>
            <pose relative_to='world'>0 0 0 0 0 0</pose>   <!--the pose is relative to the world by default-->
            <!--chassis-->
            <link name='chassis'>   
                <pose relative_to='__model__'>0.5 0 0.4 0 0 0</pose> 
                <inertial> <!--inertial properties of the link mass, inertia matix-->
                    <mass>1.14395</mass>
                    <inertia>
                        <ixx>0.095329</ixx>
                        <ixy>0</ixy>
                        <ixz>0</ixz>
                        <iyy>0.381317</iyy>
                        <iyz>0</iyz>
                        <izz>0.476646</izz>
                    </inertia>
                </inertial>
                <visual name='visual'>
                    <geometry>
                        <box>
                            <size>2.0 1.0 0.5</size> 
                        </box>
                    </geometry>
                    <!--Color of the link-->
                    <material>
                        <ambient>0.0 0.0 1.0 1</ambient>
                        <diffuse>0.0 0.0 1.0 1</diffuse>
                        <specular>0.0 0.0 1.0 1</specular>
                    </material>
                </visual>
                <collision name='collision'>
                    <geometry>
                        <box>
                            <size>2.0 1.0 0.5</size>
                        </box>
                    </geometry>
                </collision>
            </link>

            <!--Left wheel-->
            <link name='left_wheel'> 
                <pose relative_to="chassis">-0.5 0.6 0 -1.5707 0 0</pose> <!--angles are in radian-->
                <inertial>
                    <mass>1</mass>
                    <inertia>
                        <ixx>0.043333</ixx>
                        <ixy>0</ixy>
                        <ixz>0</ixz>
                        <iyy>0.043333</iyy>
                        <iyz>0</iyz>
                        <izz>0.08</izz>
                    </inertia>
                </inertial>
                <visual name='visual'>
                    <geometry>
                        <cylinder>
                            <radius>0.4</radius> 
                            <length>0.2</length>
                        </cylinder>
                    </geometry>
                    <material>
                        <ambient>1.0 0.0 0.0 1</ambient>
                        <diffuse>1.0 0.0 0.0 1</diffuse>
                        <specular>1.0 0.0 0.0 1</specular>
                    </material>
                </visual>
                <collision name='collision'>
                    <geometry>
                        <cylinder>
                            <radius>0.4</radius>
                            <length>0.2</length>
                        </cylinder>
                    </geometry>
                </collision>
            </link>

            <!--The same as left wheel but with different position-->
            <link name='right_wheel'>
                <pose relative_to="chassis">-0.5 -0.6 0 -1.5707 0 0</pose> <!--angles are in radian-->
                <inertial>
                    <mass>1</mass>
                    <inertia>
                        <ixx>0.043333</ixx>
                        <ixy>0</ixy>
                        <ixz>0</ixz>
                        <iyy>0.043333</iyy>
                        <iyz>0</iyz>
                        <izz>0.08</izz>
                    </inertia>
                </inertial>
                <visual name='visual'>
                    <geometry>
                        <cylinder>
                            <radius>0.4</radius>
                            <length>0.2</length>
                        </cylinder>
                    </geometry>
                    <material>
                        <ambient>1.0 0.0 0.0 1</ambient>
                        <diffuse>1.0 0.0 0.0 1</diffuse>
                        <specular>1.0 0.0 0.0 1</specular>
                    </material>
                </visual>
                <collision name='collision'>
                    <geometry>
                        <cylinder>
                            <radius>0.4</radius>
                            <length>0.2</length>
                        </cylinder>
                    </geometry>
                </collision>
            </link>

            <!--arbitrary frame-->
            <frame name="caster_frame" attached_to='chassis'>
                <pose>0.8 0 -0.2 0 0 0</pose>
            </frame>

            <!--caster wheel-->
            <link name='caster'>
                <pose relative_to='caster_frame'/>
                <inertial>
                    <mass>1</mass>
                    <inertia>
                        <ixx>0.016</ixx>
                        <ixy>0</ixy>
                        <ixz>0</ixz>
                        <iyy>0.016</iyy>
                        <iyz>0</iyz>
                        <izz>0.016</izz>
                    </inertia>
                </inertial>
                <visual name='visual'>
                    <geometry>
                        <sphere>
                            <radius>0.2</radius>
                        </sphere>
                    </geometry>
                    <material>
                        <ambient>0.0 1 0.0 1</ambient>
                        <diffuse>0.0 1 0.0 1</diffuse>
                        <specular>0.0 1 0.0 1</specular>
                    </material>
                </visual>
                <collision name='collision'>
                    <geometry>
                        <sphere>
                            <radius>0.2</radius>
                        </sphere>
                    </geometry>
                </collision>
            </link>

            <!--left wheel joint-->
            <joint name='left_wheel_joint' type='revolute'>
                <pose relative_to='left_wheel'/>
                <parent>chassis</parent>
                <child>left_wheel</child>
                <axis>
                    <xyz expressed_in='__model__'>0 1 0</xyz> <!--can be descired to any frame or even arbitrary frames-->
                    <limit>
                        <lower>-1.79769e+308</lower>    <!--negative infinity-->
                        <upper>1.79769e+308</upper>     <!--positive infinity-->
                    </limit>
                </axis>
            </joint>

            <!--right wheel joint-->
            <joint name='right_wheel_joint' type='revolute'>
                <pose relative_to='right_wheel'/>
                <parent>chassis</parent>
                <child>right_wheel</child>
                <axis>
                    <xyz expressed_in='__model__'>0 1 0</xyz>
                    <limit>
                        <lower>-1.79769e+308</lower>    <!--negative infinity-->
                        <upper>1.79769e+308</upper>     <!--positive infinity-->
                    </limit>
                </axis>
            </joint>

            <!--caster wheel joint--> <!--pose defult value is the child-->
            <joint name='caster_wheel' type='ball'>
                <parent>chassis</parent>
                <child>caster</child>
            </joint>


            <plugin
                filename="libignition-gazebo-diff-drive-system.so"
                name="ignition::gazebo::systems::DiffDrive">
                <left_joint>left_wheel_joint</left_joint>
                <right_joint>right_wheel_joint</right_joint>
                <wheel_separation>1.2</wheel_separation>
                <wheel_radius>0.4</wheel_radius>
                <odom_publish_frequency>1</odom_publish_frequency>
                <topic>cmd_vel</topic>
            </plugin>
    </model>
    
  </world>
</sdf>
