<?xml version="1.0" ?>
<sdf version="1.6">
  <world name="segmentation_world">
    <plugin
      filename="ignition-gazebo-physics-system"
      name="ignition::gazebo::systems::Physics">
    </plugin>
    <plugin
      filename="ignition-gazebo-user-commands-system"
      name="ignition::gazebo::systems::UserCommands">
    </plugin>
    <plugin
      filename="ignition-gazebo-scene-broadcaster-system"
      name="ignition::gazebo::systems::SceneBroadcaster">
    </plugin>
    <plugin
      filename="ignition-gazebo-sensors-system"
      name="ignition::gazebo::systems::Sensors">
      <render_engine>ogre2</render_engine>
    </plugin>

    <gui fullscreen="1">

      <!-- 3D scene -->
      <plugin filename="MinimalScene" name="3D View">
        <ignition-gui>
          <title>3D View</title>
          <property type="bool" key="showTitleBar">false</property>
          <property type="string" key="state">docked</property>
        </ignition-gui>

        <engine>ogre2</engine>
        <scene>scene</scene>
        <ambient_light>0.4 0.4 0.4</ambient_light>
        <background_color>0.8 0.8 0.8</background_color>
        <camera_pose>-6 0 6 0 0.5 0</camera_pose>
      </plugin>

      <!-- Plugins that add functionality to the scene -->
      <plugin filename="EntityContextMenuPlugin" name="Entity context menu">
        <ignition-gui>
          <property key="state" type="string">floating</property>
          <property key="width" type="double">5</property>
          <property key="height" type="double">5</property>
          <property key="showTitleBar" type="bool">false</property>
        </ignition-gui>
      </plugin>
      <plugin filename="GzSceneManager" name="Scene Manager">
        <ignition-gui>
          <property key="resizable" type="bool">false</property>
          <property key="width" type="double">5</property>
          <property key="height" type="double">5</property>
          <property key="state" type="string">floating</property>
          <property key="showTitleBar" type="bool">false</property>
        </ignition-gui>
      </plugin>
      <plugin filename="InteractiveViewControl" name="Interactive view control">
        <ignition-gui>
          <property key="resizable" type="bool">false</property>
          <property key="width" type="double">5</property>
          <property key="height" type="double">5</property>
          <property key="state" type="string">floating</property>
          <property key="showTitleBar" type="bool">false</property>
        </ignition-gui>
      </plugin>
      <plugin filename="CameraTracking" name="Camera Tracking">
        <ignition-gui>
          <property key="resizable" type="bool">false</property>
          <property key="width" type="double">5</property>
          <property key="height" type="double">5</property>
          <property key="state" type="string">floating</property>
          <property key="showTitleBar" type="bool">false</property>
        </ignition-gui>
      </plugin>
      <!-- World control -->
      <plugin filename="WorldControl" name="World control">
        <ignition-gui>
          <title>World control</title>
          <property type="bool" key="showTitleBar">false</property>
          <property type="bool" key="resizable">false</property>
          <property type="double" key="height">72</property>
          <property type="double" key="width">121</property>
          <property type="double" key="z">1</property>

          <property type="string" key="state">floating</property>
          <anchors target="3D View">
            <line own="left" target="left"/>
            <line own="bottom" target="bottom"/>
          </anchors>
        </ignition-gui>

        <play_pause>true</play_pause>
        <step>true</step>
        <start_paused>true</start_paused>
        <use_event>true</use_event>

      </plugin>

      <!-- World statistics -->
      <plugin filename="WorldStats" name="World stats">
        <ignition-gui>
          <title>World stats</title>
          <property type="bool" key="showTitleBar">false</property>
          <property type="bool" key="resizable">false</property>
          <property type="double" key="height">110</property>
          <property type="double" key="width">290</property>
          <property type="double" key="z">1</property>

          <property type="string" key="state">floating</property>
          <anchors target="3D View">
            <line own="right" target="right"/>
            <line own="bottom" target="bottom"/>
          </anchors>
        </ignition-gui>

        <sim_time>true</sim_time>
        <real_time>true</real_time>
        <real_time_factor>true</real_time_factor>
        <iterations>true</iterations>
      </plugin>

      <!-- Inspector -->
      <plugin filename="ComponentInspector" name="Component inspector">
        <ignition-gui>
          <property type="string" key="state">docked_collapsed</property>
        </ignition-gui>
      </plugin>

      <!-- Entity tree -->
      <plugin filename="EntityTree" name="Entity tree">
        <ignition-gui>
          <property type="string" key="state">docked_collapsed</property>
        </ignition-gui>
      </plugin>

      <!-- Image Display Plugins for visualization -->
      <plugin filename="ImageDisplay" name="Image Display">
        <ignition-gui>
        </ignition-gui>
        <topic>semantic/colored_map</topic>
      </plugin>

      <plugin filename="VisualizeLidar" name="Visualize Lidar">
        <ignition-gui>
          <property key="state" type="string">docked</property>
        </ignition-gui>
      </plugin>
    </gui>

    <light type="directional" name="sun">
      <cast_shadows>true</cast_shadows>
      <pose>0 0 10 0 0 0</pose>
      <diffuse>0.8 0.8 0.8 1</diffuse>
      <specular>0.2 0.2 0.2 1</specular>
      <attenuation>
        <range>1000</range>
        <constant>0.9</constant>
        <linear>0.01</linear>
        <quadratic>0.001</quadratic>
      </attenuation>
      <direction>-0.5 0.1 -0.9</direction>
    </light>

    <model name="ground_plane">
      <static>true</static>
      <link name="link">
        <collision name="collision">
          <geometry>
            <plane>
              <normal>0 0 1</normal>
              <size>100 100</size>
            </plane>
          </geometry>
        </collision>
        <visual name="visual">
          <geometry>
            <plane>
              <normal>0 0 1</normal>
              <size>100 100</size>
            </plane>
          </geometry>
          <material>
            <ambient>0.8 0.8 0.8 1</ambient>
            <diffuse>0.8 0.8 0.8 1</diffuse>
            <specular>0.8 0.8 0.8 1</specular>
          </material>
        </visual>
      </link>
    </model>

    <!-- Cars, all of them have label 40 -->
    <include>
      <name>Car1</name>
      <pose>-2 -2 0 0 0 0</pose>
      <uri>
        https://fuel.ignitionrobotics.org/1.0/OpenRobotics/models/Hatchback blue
      </uri>
      <plugin filename="ignition-gazebo-label-system" name="ignition::gazebo::systems::Label">
        <label>40</label>
      </plugin>
    </include>

    <include>
      <name>Car2</name>
      <pose>-3 -5 0 0 0 0</pose>
      <uri>
        https://fuel.ignitionrobotics.org/1.0/OpenRobotics/models/Pickup
      </uri>
      <plugin filename="ignition-gazebo-label-system" name="ignition::gazebo::systems::Label">
        <label>40</label>
      </plugin>
    </include>

    <include>
      <name>Car3</name>
      <pose>-4 3 0 0 0 -1.57</pose>
      <uri>
        https://fuel.ignitionrobotics.org/1.0/OpenRobotics/models/SUV
      </uri>
      <plugin filename="ignition-gazebo-label-system" name="ignition::gazebo::systems::Label">
        <label>40</label>
      </plugin>
    </include>

    <!-- Tree, all of them have label 30 -->
    <include>
      <name>tree1</name>
      <pose>-2 5 0 0 0 0</pose>
      <uri>
        https://fuel.ignitionrobotics.org/1.0/OpenRobotics/models/Pine Tree
      </uri>
      <plugin filename="ignition-gazebo-label-system" name="ignition::gazebo::systems::Label">
        <label>30</label>
      </plugin>
    </include>

    <include>
      <name>tree2</name>
      <pose>-7 2 0 0 0 0</pose>
      <uri>
        https://fuel.ignitionrobotics.org/1.0/OpenRobotics/models/Pine Tree
      </uri>
      <plugin filename="ignition-gazebo-label-system" name="ignition::gazebo::systems::Label">
        <label>30</label>
      </plugin>
    </include>

    <include>
      <name>tree3</name>
      <pose>-7 -4 0 0 0 0</pose>
      <uri>
        https://fuel.ignitionrobotics.org/1.0/OpenRobotics/models/Pine Tree
      </uri>
      <plugin filename="ignition-gazebo-label-system" name="ignition::gazebo::systems::Label">
        <label>30</label>
      </plugin>
    </include>
    
    <!-- Stairs, all of them have label 5 -->
    <model name="stairs 1" >
      <pose>50 0 0  0 0 0</pose>
      <static>true</static>
      <link name="body" >
        <visual name="visual">
          <plugin filename="ignition-gazebo-label-system" name="ignition::gazebo::systems::Label">
            <label>20</label>
          </plugin>
          <geometry>
            <mesh>
             <scale>.1 .1 .1</scale>
             <uri>meshes/stairs_0020.dae</uri>
            </mesh>
          </geometry>
        </visual>
      </link>
    </model>


    <!-- Cones, all with label 20-->
    <include>
      <name>cone2</name>
      <pose>0 4 0 0 0 1.570796</pose>
      <uri>
        https://fuel.ignitionrobotics.org/1.0/OpenRobotics/models/Construction Cone
      </uri>
      <plugin filename="ignition-gazebo-label-system" name="ignition::gazebo::systems::Label">
        <label>20</label>
      </plugin>
    </include>

    <include>
      <name>cone3</name>
      <pose>2 -2 0 0 0.0 1.57</pose>
      <uri>
        https://fuel.ignitionrobotics.org/1.0/OpenRobotics/models/Construction Cone
      </uri>
      <plugin filename="ignition-gazebo-label-system" name="ignition::gazebo::systems::Label">
        <label>20</label>
      </plugin>
    </include>


    <model name='vehicle_blue'>
          <pose>0 0 0.325 0 0 0.0</pose>
          <link name='chassis'>
            <pose>-0.151427 -0 0.175 0 -0 0</pose>
            <inertial>
              <mass>1.14395</mass>
              <inertia>
                <ixx>0.126164</ixx>
                <ixy>0</ixy>
                <ixz>0</ixz>
                <iyy>0.416519</iyy>
                <iyz>0</iyz>
                <izz>0.481014</izz>
              </inertia>
            </inertial>
            <visual name='visual'>
              <geometry>
                <box>
                  <size>2.01142 1 0.568726</size>
                </box>
              </geometry>
              <material>
                <ambient>0.5 0.5 1.0 1</ambient>
                <diffuse>0.5 0.5 1.0 1</diffuse>
                <specular>0.0 0.0 1.0 1</specular>
              </material>
            </visual>
            <collision name='collision'>
              <geometry>
                <box>
                  <size>2.01142 1 0.568726</size>
                </box>
              </geometry>
            </collision>
          </link>
    
          <link name="lidar_link">
            <pose>0 0 0.5 0 0 0</pose>
            <inertial>
              <mass>0.1</mass>
              <inertia>
                <ixx>0.000166667</ixx>
                <iyy>0.000166667</iyy>
                <izz>0.000166667</izz>
              </inertia>
            </inertial>
            <collision name="collision">
              <geometry>
                <box>
                  <size>0.1 0.1 0.1</size>
                </box>
              </geometry>
            </collision>
            <visual name="visual">
              <geometry>
                <box>
                  <size>0.1 0.1 0.1</size>
                </box>
              </geometry>
            </visual>
            <sensor name='gpu_lidar' type='gpu_lidar'>
            <pose>0 0 0 0 0 0</pose>
              <topic>lidar</topic>
              <update_rate>10</update_rate>
              <lidar>
                <scan>
                  <horizontal>
                    <samples>640</samples>
                    <resolution>1</resolution>
                    <min_angle>-1.396263</min_angle>
                    <max_angle>1.396263</max_angle>
                  </horizontal>
                  <vertical>
                    <samples>1</samples>
                    <resolution>1</resolution>
                    <min_angle>0.0</min_angle>
                    <max_angle>0.0</max_angle>
                  </vertical>
                </scan>
                <range>
                  <min>0.08</min>
                  <max>10.0</max>
                  <resolution>0.01</resolution>
                </range>
              </lidar>
              <alwaysOn>1</alwaysOn>
              <visualize>true</visualize>
            </sensor>
          </link>
          <link name="semantic_camera_link">
            <pose>0 0.0 0.5 0 0 0</pose>
            <inertial>
              <mass>0.1</mass>
              <inertia>
                <ixx>0.000166667</ixx>
                <iyy>0.000166667</iyy>
                <izz>0.000166667</izz>
              </inertia>
            </inertial>
            <collision name="collision">
              <geometry>
                <box>
                  <size>0.1 0.1 0.1</size>
                </box>
              </geometry>
            </collision>
            <visual name="visual">
              <geometry>
                <box>
                  <size>0.1 0.1 0.1</size>
                </box>
              </geometry>
            </visual>
            <sensor name="semantic_segmentation_camera" type="segmentation">
              <topic>semantic</topic>
              <camera>
                <segmentation_type>semantic</segmentation_type>
                <horizontal_fov>1.57</horizontal_fov>
                <image>
                  <width>800</width>
                  <height>600</height>
                </image>
                <clip>
                  <near>0.1</near>
                  <far>100</far>
                </clip>
                <!-- uncomment these lines to save segmentation data -->
                <!--
                <save enabled="true">
                  <path>segmentation_data/semantic_camera</path>
                </save>
                -->
              </camera>
              <always_on>1</always_on>
              <update_rate>30</update_rate>
              <visualize>true</visualize>
            </sensor>
          </link>
          <link name='left_wheel'>
            <pose>0.554283 0.625029 -0.025 -1.5707 0 0</pose>
            <inertial>
              <mass>2</mass>
              <inertia>
                <ixx>0.145833</ixx>
                <ixy>0</ixy>
                <ixz>0</ixz>
                <iyy>0.145833</iyy>
                <iyz>0</iyz>
                <izz>0.125</izz>
              </inertia>
            </inertial>
            <visual name='visual'>
              <geometry>
                <sphere>
                  <radius>0.3</radius>
                </sphere>
              </geometry>
              <material>
                <ambient>0.2 0.2 0.2 1</ambient>
                <diffuse>0.2 0.2 0.2 1</diffuse>
                <specular>0.2 0.2 0.2 1</specular>
              </material>
            </visual>
            <collision name='collision'>
              <geometry>
                <sphere>
                  <radius>0.3</radius>
                </sphere>
              </geometry>
            </collision>
          </link>
    
          <link name='right_wheel'>
            <pose>0.554282 -0.625029 -0.025 -1.5707 0 0</pose>
            <inertial>
              <mass>2</mass>
              <inertia>
                <ixx>0.145833</ixx>
                <ixy>0</ixy>
                <ixz>0</ixz>
                <iyy>0.145833</iyy>
                <iyz>0</iyz>
                <izz>0.125</izz>
              </inertia>
            </inertial>
            <visual name='visual'>
              <geometry>
                <sphere>
                  <radius>0.3</radius>
                </sphere>
              </geometry>
              <material>
                <ambient>0.2 0.2 0.2 1</ambient>
                <diffuse>0.2 0.2 0.2 1</diffuse>
                <specular>0.2 0.2 0.2 1</specular>
              </material>
            </visual>
            <collision name='collision'>
              <geometry>
                <sphere>
                  <radius>0.3</radius>
                </sphere>
              </geometry>
            </collision>
          </link>
    
          <link name='caster'>
            <pose>-0.957138 -0 -0.125 0 -0 0</pose>
            <inertial>
              <mass>1</mass>
              <inertia>
                <ixx>0.1</ixx>
                <ixy>0</ixy>
                <ixz>0</ixz>
                <iyy>0.1</iyy>
                <iyz>0</iyz>
                <izz>0.1</izz>
              </inertia>
            </inertial>
            <visual name='visual'>
              <geometry>
                <sphere>
                  <radius>0.2</radius>
                </sphere>
              </geometry>
              <material>
                <ambient>0.2 0.2 0.2 1</ambient>
                <diffuse>0.2 0.2 0.2 1</diffuse>
                <specular>0.2 0.2 0.2 1</specular>
              </material>
            </visual>
            <collision name='collision'>
              <geometry>
                <sphere>
                  <radius>0.2</radius>
                </sphere>
              </geometry>
            </collision>
          </link>
    
          <joint name='lidar_sensor_joint' type='fixed'>
            <parent>chassis</parent>
            <child>lidar_link</child>
          </joint>
          <joint name='segmentation_camera_sensor_joint' type='fixed'>
            <parent>chassis</parent>
            <child>semantic_camera_link</child>
          </joint>

          <joint name='left_wheel_joint' type='revolute'>
            <parent>chassis</parent>
            <child>left_wheel</child>
            <axis>
              <xyz>0 0 1</xyz>
              <limit>
                <lower>-1.79769e+308</lower>
                <upper>1.79769e+308</upper>
              </limit>
            </axis>
          </joint>
    
          <joint name='right_wheel_joint' type='revolute'>
            <parent>chassis</parent>
            <child>right_wheel</child>
            <axis>
              <xyz>0 0 1</xyz>
              <limit>
                <lower>-1.79769e+308</lower>
                <upper>1.79769e+308</upper>
              </limit>
            </axis>
          </joint>
    
          <joint name='caster_wheel' type='ball'>
            <parent>chassis</parent>
            <child>caster</child>
          </joint>
    
          <plugin
            filename="libignition-gazebo-diff-drive-system.so"
            name="ignition::gazebo::systems::DiffDrive">
            <left_joint>left_wheel_joint</left_joint>
            <right_joint>right_wheel_joint</right_joint>
            <wheel_separation>1.25</wheel_separation>
            <wheel_radius>0.3</wheel_radius>
            <odom_publish_frequency>1</odom_publish_frequency>
            <topic>cmd_vel</topic>
          </plugin>
        </model>

    
  </world>
</sdf>
